<robot name="simple">

  <link name="world"/>
  <link name="robot_link_0">
    <visual>
      <origin xyz="0 0 0.25" rpy="0 0 0" />
      <geometry>
        <box size="0.5 0.5 0.5"/>
      </geometry>
    </visual>
  </link>
  
  <joint name="q0" type="fixed">
    <origin xyz="0 0 0" rpy="0 0 0"/>
    <parent link="world"/>
    <child link="robot_link_0"/>
    <axis xyz="0 0 1"/>

    <limit lower="-1" upper="1" effort="1" velocity="1"/>
  </joint>


  <link name="robot_link_1">
    <visual>
      <origin xyz="0 0 0.25" rpy="0 0 0" />
      <geometry>
        <cylinder radius="0.1"  length="0.5"/>
      </geometry>
    </visual>
  </link>
  
  <joint name="robot_joint_1" type="revolute">
    <origin xyz="0 0 0.5" rpy="0 0 0"/>
    <parent link="robot_link_0"/>
    <child link="robot_link_1"/>
    <axis xyz="0 0 1"/>

    <limit lower="-1" upper="1" effort="1" velocity="1"/>

  </joint>

  <link name="robot_link_2">
    <visual>
      <origin xyz="0 0 0.25" rpy="0 0 0" />
      <geometry>
        <cylinder radius="0.1"  length="0.5"/>
      </geometry>
    </visual>
  </link>
  
  <joint name="robot_joint_2" type="revolute">
    <origin xyz="0 0 0.5" rpy="1.57 0 0"/>
    <parent link="robot_link_1"/>
    <child link="robot_link_2"/>
    <axis xyz="1 0 0"/>

    <limit lower="-1" upper="1" effort="1" velocity="1"/>

  </joint>

  
  <link name="robot_flange">
  </link>

  <joint name="q1" type="fixed">
    <origin xyz="0 0 0.5" rpy="0 0 0"/>
    <parent link="robot_link_2"/>
    <child link="robot_flange"/>
    <axis xyz="0 0 1"/>

    <limit lower="-1" upper="1" effort="1" velocity="1"/>
  </joint>

</robot>
