<?xml version="1.0" ?>
<!-- =================================================================================== -->
<!-- |    This document was autogenerated by xacro from ./edumip.urdf.xacro            | -->
<!-- |    EDITING THIS FILE BY HAND IS NOT RECOMMENDED                                 | -->
<!-- =================================================================================== -->
<robot name="robot" xmlns:xacro="http://www.ros.org/wiki/xacro">
  <link name="world"/>
  <link name="base_link">
    <visual>
      <origin rpy="0 -0.20 0" xyz="0 0 0.05"/>
      <geometry>
        <box size="0.035 0.05 0.1"/>
      </geometry>
      <material name="Blue">
        <color rgba="0 0.0 1.0 0.5"/>
      </material>
    </visual>
    <collision>
      <origin rpy="0 -0.20 0" xyz="0 0 0.05"/>
      <geometry>
        <box size="0.035 0.05 0.1"/>
      </geometry>
    </collision>
    <inertial>
      <origin rpy="0 0 0" xyz="0 0 0.05"/>
      <mass value="0.180"/>
      <inertia ixx="6.0e-4" ixy="0" ixz="0" iyy="6.0e-4" iyz="0" izz="6.0e-4"/>
    </inertial>
  </link>
  <link name="left_wheel">
    <inertial>
      <origin rpy="0 0 0" xyz="0 0 0"/>
      <mass value="0.030"/>
      <inertia ixx="1.75e-5" ixy="0" ixz="0" iyy="1.75e-5" iyz="0" izz="1.75e-5"/>
    </inertial>
    <visual>
      <!-- <origin xyz="0 0 0" rpy="1.57 0 0" /> -->
      <origin rpy="1.57 0 0 " xyz="0 0.035 0"/>
      <geometry>
        <cylinder length="0.01" radius="0.034"/>
      </geometry>
    </visual>
  </link>
  <link name="right_wheel">
    <inertial>
      <origin rpy="0 0 0" xyz="0 0 0"/>
      <mass value="0.030"/>
      <inertia ixx="1.75e-5" ixy="0" ixz="0" iyy="1.75e-5" iyz="0" izz="1.75e-5"/>
    </inertial>
    <visual>
      <!-- <origin xyz="0 0 0" rpy="1.57 0 0" /> -->
      <origin rpy="1.57 0 0 " xyz="0 -0.035 0"/>
      <geometry>
        <cylinder length="0.01" radius="0.034"/>
      </geometry>
    </visual>
  </link>
  <joint name="q0" type="floating">
    <origin rpy="0 0 0" xyz="0 0 0"/>
    <parent link="world"/>
    <child link="base_link"/>
    <axis xyz="0 0 1"/>
  </joint>
  <joint name="q1" type="continuous">
    <!-- <xacro:insert_block name="left_origin" /> -->
    <parent link="base_link"/>
    <child link="left_wheel"/>
    <axis xyz="0 1 0"/>
  </joint>
  <joint name="q2" type="continuous">
    <!-- <xacro:insert_block name="right_origin" /> -->
    <parent link="base_link"/>
    <child link="right_wheel"/>
    <axis xyz="0 1 0"/>
  </joint>
  <!--   

  <joint name="q3" type="fixed">
    <origin xyz="0 0 0.5" rpy="0 0 0"/>
    <parent link="robot_link_2"/>
    <child link="robot_flange"/>
    <axis xyz="0 0 1"/>

    <limit lower="-1" upper="1" effort="1" velocity="1"/>
  </joint> -->
</robot>
